Workbook

Sheet flowssummary
A1: Category | B1: Type | C1: 1 | D1: 2 | E1: 3 | F1: 4 | G1: 5 | H1: 6 | I1: 7 | J1: 8 | K1: 9 | L1: 10 | M1: 11 | N1: 12
A2: Bank | B2: Product | C2: Opening balance | D2: Operation | E2: Closing balance | F2: {=SUMIFS(operations[[Amount]:[Amount]],operations[[Category]:[Category]],summary17[[#This Row],[Category]:[Category]],operations[[Month]:[Month]],summary17[[#Headers],[4]])} -> 0 | G2: {=SUMIFS(operations[[Amount]:[Amount]],operations[[Category]:[Category]],summary17[[#This Row],[Category]:[Category]],operations[[Month]:[Month]],summary17[[#Headers],[5]])} -> 0 | H2: {=SUMIFS(operations[[Amount]:[Amount]],operations[[Category]:[Category]],summary17[[#This Row],[Category]:[Category]],operations[[Month]:[Month]],summary17[[#Headers],[6]])} -> 0 | I2: {=SUMIFS(operations[[Amount]:[Amount]],operations[[Category]:[Category]],summary17[[#This Row],[Category]:[Category]],operations[[Month]:[Month]],summary17[[#Headers],[7]])} -> 0 | J2: {=SUMIFS(operations[[Amount]:[Amount]],operations[[Category]:[Category]],summary17[[#This Row],[Category]:[Category]],operations[[Month]:[Month]],summary17[[#Headers],[8]])} -> 0 | K2: {=SUMIFS(operations[[Amount]:[Amount]],operations[[Category]:[Category]],summary17[[#This Row],[Category]:[Category]],operations[[Month]:[Month]],summary17[[#Headers],[9]])} -> 0 | L2: {=SUMIFS(operations[[Amount]:[Amount]],operations[[Category]:[Category]],summary17[[#This Row],[Category]:[Category]],operations[[Month]:[Month]],summary17[[#Headers],[10]])} -> 0 | M2: {=SUMIFS(operations[[Amount]:[Amount]],operations[[Category]:[Category]],summary17[[#This Row],[Category]:[Category]],operations[[Month]:[Month]],summary17[[#Headers],[11]])} -> 0 | N2: {=SUMIFS(operations[[Amount]:[Amount]],operations[[Category]:[Category]],summary17[[#This Row],[Category]:[Category]],operations[[Month]:[Month]],summary17[[#Headers],[12]])} -> 0
A3: Millennium | B3: Account | C3: 100 | D3: -35 | E3: 65 | F3: {=SUMIFS(operations[[Amount]:[Amount]],operations[[Category]:[Category]],summary17[[#This Row],[Category]:[Category]],operations[[Month]:[Month]],summary17[[#Headers],[4]])} -> 0 | G3: {=SUMIFS(operations[[Amount]:[Amount]],operations[[Category]:[Category]],summary17[[#This Row],[Category]:[Category]],operations[[Month]:[Month]],summary17[[#Headers],[5]])} -> 0 | H3: {=SUMIFS(operations[[Amount]:[Amount]],operations[[Category]:[Category]],summary17[[#This Row],[Category]:[Category]],operations[[Month]:[Month]],summary17[[#Headers],[6]])} -> 0 | I3: {=SUMIFS(operations[[Amount]:[Amount]],operations[[Category]:[Category]],summary17[[#This Row],[Category]:[Category]],operations[[Month]:[Month]],summary17[[#Headers],[7]])} -> 0 | J3: {=SUMIFS(operations[[Amount]:[Amount]],operations[[Category]:[Category]],summary17[[#This Row],[Category]:[Category]],operations[[Month]:[Month]],summary17[[#Headers],[8]])} -> 0 | K3: {=SUMIFS(operations[[Amount]:[Amount]],operations[[Category]:[Category]],summary17[[#This Row],[Category]:[Category]],operations[[Month]:[Month]],summary17[[#Headers],[9]])} -> 0 | L3: {=SUMIFS(operations[[Amount]:[Amount]],operations[[Category]:[Category]],summary17[[#This Row],[Category]:[Category]],operations[[Month]:[Month]],summary17[[#Headers],[10]])} -> 0 | M3: {=SUMIFS(operations[[Amount]:[Amount]],operations[[Category]:[Category]],summary17[[#This Row],[Category]:[Category]],operations[[Month]:[Month]],summary17[[#Headers],[11]])} -> 0 | N3: {=SUMIFS(operations[[Amount]:[Amount]],operations[[Category]:[Category]],summary17[[#This Row],[Category]:[Category]],operations[[Month]:[Month]],summary17[[#Headers],[12]])} -> 0
A4: Millennium | B4: Savings account | C4: 10.5 | D4: 255.5 | E4: 266 | F4: {=SUMIFS(operations[[Amount]:[Amount]],operations[[Category]:[Category]],summary17[[#This Row],[Category]:[Category]],operations[[Month]:[Month]],summary17[[#Headers],[4]])} -> 0 | G4: {=SUMIFS(operations[[Amount]:[Amount]],operations[[Category]:[Category]],summary17[[#This Row],[Category]:[Category]],operations[[Month]:[Month]],summary17[[#Headers],[5]])} -> 0 | H4: {=SUMIFS(operations[[Amount]:[Amount]],operations[[Category]:[Category]],summary17[[#This Row],[Category]:[Category]],operations[[Month]:[Month]],summary17[[#Headers],[6]])} -> 0 | I4: {=SUMIFS(operations[[Amount]:[Amount]],operations[[Category]:[Category]],summary17[[#This Row],[Category]:[Category]],operations[[Month]:[Month]],summary17[[#Headers],[7]])} -> 0 | J4: {=SUMIFS(operations[[Amount]:[Amount]],operations[[Category]:[Category]],summary17[[#This Row],[Category]:[Category]],operations[[Month]:[Month]],summary17[[#Headers],[8]])} -> 0 | K4: {=SUMIFS(operations[[Amount]:[Amount]],operations[[Category]:[Category]],summary17[[#This Row],[Category]:[Category]],operations[[Month]:[Month]],summary17[[#Headers],[9]])} -> 0 | L4: {=SUMIFS(operations[[Amount]:[Amount]],operations[[Category]:[Category]],summary17[[#This Row],[Category]:[Category]],operations[[Month]:[Month]],summary17[[#Headers],[10]])} -> 0 | M4: {=SUMIFS(operations[[Amount]:[Amount]],operations[[Category]:[Category]],summary17[[#This Row],[Category]:[Category]],operations[[Month]:[Month]],summary17[[#Headers],[11]])} -> 0 | N4: {=SUMIFS(operations[[Amount]:[Amount]],operations[[Category]:[Category]],summary17[[#This Row],[Category]:[Category]],operations[[Month]:[Month]],summary17[[#Headers],[12]])} -> 0
A5: Santander | B5: Account | C5: 600 | D5: 1100 | E5: 1700 | F5: {=SUMIFS(operations[[Amount]:[Amount]],operations[[Category]:[Category]],summary17[[#This Row],[Category]:[Category]],operations[[Month]:[Month]],summary17[[#Headers],[4]])} -> 0 | G5: {=SUMIFS(operations[[Amount]:[Amount]],operations[[Category]:[Category]],summary17[[#This Row],[Category]:[Category]],operations[[Month]:[Month]],summary17[[#Headers],[5]])} -> 0 | H5: {=SUMIFS(operations[[Amount]:[Amount]],operations[[Category]:[Category]],summary17[[#This Row],[Category]:[Category]],operations[[Month]:[Month]],summary17[[#Headers],[6]])} -> 0 | I5: {=SUMIFS(operations[[Amount]:[Amount]],operations[[Category]:[Category]],summary17[[#This Row],[Category]:[Category]],operations[[Month]:[Month]],summary17[[#Headers],[7]])} -> 0 | J5: {=SUMIFS(operations[[Amount]:[Amount]],operations[[Category]:[Category]],summary17[[#This Row],[Category]:[Category]],operations[[Month]:[Month]],summary17[[#Headers],[8]])} -> 0 | K5: {=SUMIFS(operations[[Amount]:[Amount]],operations[[Category]:[Category]],summary17[[#This Row],[Category]:[Category]],operations[[Month]:[Month]],summary17[[#Headers],[9]])} -> 0 | L5: {=SUMIFS(operations[[Amount]:[Amount]],operations[[Category]:[Category]],summary17[[#This Row],[Category]:[Category]],operations[[Month]:[Month]],summary17[[#Headers],[10]])} -> 0 | M5: {=SUMIFS(operations[[Amount]:[Amount]],operations[[Category]:[Category]],summary17[[#This Row],[Category]:[Category]],operations[[Month]:[Month]],summary17[[#Headers],[11]])} -> 0 | N5: {=SUMIFS(operations[[Amount]:[Amount]],operations[[Category]:[Category]],summary17[[#This Row],[Category]:[Category]],operations[[Month]:[Month]],summary17[[#Headers],[12]])} -> 0
A6: Santander | B6: Credit card | C6: 0 | D6: -175 | E6: -175 | F6: {=SUMIFS(operations[[Amount]:[Amount]],operations[[Category]:[Category]],summary17[[#This Row],[Category]:[Category]],operations[[Month]:[Month]],summary17[[#Headers],[4]])} -> 0 | G6: {=SUMIFS(operations[[Amount]:[Amount]],operations[[Category]:[Category]],summary17[[#This Row],[Category]:[Category]],operations[[Month]:[Month]],summary17[[#Headers],[5]])} -> 0 | H6: {=SUMIFS(operations[[Amount]:[Amount]],operations[[Category]:[Category]],summary17[[#This Row],[Category]:[Category]],operations[[Month]:[Month]],summary17[[#Headers],[6]])} -> 0 | I6: {=SUMIFS(operations[[Amount]:[Amount]],operations[[Category]:[Category]],summary17[[#This Row],[Category]:[Category]],operations[[Month]:[Month]],summary17[[#Headers],[7]])} -> 0 | J6: {=SUMIFS(operations[[Amount]:[Amount]],operations[[Category]:[Category]],summary17[[#This Row],[Category]:[Category]],operations[[Month]:[Month]],summary17[[#Headers],[8]])} -> 0 | K6: {=SUMIFS(operations[[Amount]:[Amount]],operations[[Category]:[Category]],summary17[[#This Row],[Category]:[Category]],operations[[Month]:[Month]],summary17[[#Headers],[9]])} -> 0 | L6: {=SUMIFS(operations[[Amount]:[Amount]],operations[[Category]:[Category]],summary17[[#This Row],[Category]:[Category]],operations[[Month]:[Month]],summary17[[#Headers],[10]])} -> 0 | M6: {=SUMIFS(operations[[Amount]:[Amount]],operations[[Category]:[Category]],summary17[[#This Row],[Category]:[Category]],operations[[Month]:[Month]],summary17[[#Headers],[11]])} -> 0 | N6: {=SUMIFS(operations[[Amount]:[Amount]],operations[[Category]:[Category]],summary17[[#This Row],[Category]:[Category]],operations[[Month]:[Month]],summary17[[#Headers],[12]])} -> 0
A7: Santander | B7: Fixed-term deposit | C7: 2000 | D7: -400 | E7: 1600 | F7: {=SUMIFS(operations[[Amount]:[Amount]],operations[[Category]:[Category]],summary17[[#This Row],[Category]:[Category]],operations[[Month]:[Month]],summary17[[#Headers],[4]])} -> 0 | G7: {=SUMIFS(operations[[Amount]:[Amount]],operations[[Category]:[Category]],summary17[[#This Row],[Category]:[Category]],operations[[Month]:[Month]],summary17[[#Headers],[5]])} -> 0 | H7: {=SUMIFS(operations[[Amount]:[Amount]],operations[[Category]:[Category]],summary17[[#This Row],[Category]:[Category]],operations[[Month]:[Month]],summary17[[#Headers],[6]])} -> 0 | I7: {=SUMIFS(operations[[Amount]:[Amount]],operations[[Category]:[Category]],summary17[[#This Row],[Category]:[Category]],operations[[Month]:[Month]],summary17[[#Headers],[7]])} -> 0 | J7: {=SUMIFS(operations[[Amount]:[Amount]],operations[[Category]:[Category]],summary17[[#This Row],[Category]:[Category]],operations[[Month]:[Month]],summary17[[#Headers],[8]])} -> 0 | K7: {=SUMIFS(operations[[Amount]:[Amount]],operations[[Category]:[Category]],summary17[[#This Row],[Category]:[Category]],operations[[Month]:[Month]],summary17[[#Headers],[9]])} -> 0 | L7: {=SUMIFS(operations[[Amount]:[Amount]],operations[[Category]:[Category]],summary17[[#This Row],[Category]:[Category]],operations[[Month]:[Month]],summary17[[#Headers],[10]])} -> 0 | M7: {=SUMIFS(operations[[Amount]:[Amount]],operations[[Category]:[Category]],summary17[[#This Row],[Category]:[Category]],operations[[Month]:[Month]],summary17[[#Headers],[11]])} -> 0 | N7: {=SUMIFS(operations[[Amount]:[Amount]],operations[[Category]:[Category]],summary17[[#This Row],[Category]:[Category]],operations[[Month]:[Month]],summary17[[#Headers],[12]])} -> 0
A8: Wallet | B8: Gift card | C8: 200 | D8: -50 | E8: 150 | F8: {=SUMIFS(operations[[Amount]:[Amount]],operations[[Category]:[Category]],summary17[[#This Row],[Category]:[Category]],operations[[Month]:[Month]],summary17[[#Headers],[4]])} -> 0 | G8: {=SUMIFS(operations[[Amount]:[Amount]],operations[[Category]:[Category]],summary17[[#This Row],[Category]:[Category]],operations[[Month]:[Month]],summary17[[#Headers],[5]])} -> 0 | H8: {=SUMIFS(operations[[Amount]:[Amount]],operations[[Category]:[Category]],summary17[[#This Row],[Category]:[Category]],operations[[Month]:[Month]],summary17[[#Headers],[6]])} -> 0 | I8: {=SUMIFS(operations[[Amount]:[Amount]],operations[[Category]:[Category]],summary17[[#This Row],[Category]:[Category]],operations[[Month]:[Month]],summary17[[#Headers],[7]])} -> 0 | J8: {=SUMIFS(operations[[Amount]:[Amount]],operations[[Category]:[Category]],summary17[[#This Row],[Category]:[Category]],operations[[Month]:[Month]],summary17[[#Headers],[8]])} -> 0 | K8: {=SUMIFS(operations[[Amount]:[Amount]],operations[[Category]:[Category]],summary17[[#This Row],[Category]:[Category]],operations[[Month]:[Month]],summary17[[#Headers],[9]])} -> 0 | L8: {=SUMIFS(operations[[Amount]:[Amount]],operations[[Category]:[Category]],summary17[[#This Row],[Category]:[Category]],operations[[Month]:[Month]],summary17[[#Headers],[10]])} -> 0 | M8: {=SUMIFS(operations[[Amount]:[Amount]],operations[[Category]:[Category]],summary17[[#This Row],[Category]:[Category]],operations[[Month]:[Month]],summary17[[#Headers],[11]])} -> 0 | N8: {=SUMIFS(operations[[Amount]:[Amount]],operations[[Category]:[Category]],summary17[[#This Row],[Category]:[Category]],operations[[Month]:[Month]],summary17[[#Headers],[12]])} -> 0
A9: Wallet | B9: Money | C9: 30 | D9: 150 | E9: 180 | F9: {=SUMIFS(operations[[Amount]:[Amount]],operations[[Category]:[Category]],summary17[[#This Row],[Category]:[Category]],operations[[Month]:[Month]],summary17[[#Headers],[4]])} -> 0 | G9: {=SUMIFS(operations[[Amount]:[Amount]],operations[[Category]:[Category]],summary17[[#This Row],[Category]:[Category]],operations[[Month]:[Month]],summary17[[#Headers],[5]])} -> 0 | H9: {=SUMIFS(operations[[Amount]:[Amount]],operations[[Category]:[Category]],summary17[[#This Row],[Category]:[Category]],operations[[Month]:[Month]],summary17[[#Headers],[6]])} -> 0 | I9: {=SUMIFS(operations[[Amount]:[Amount]],operations[[Category]:[Category]],summary17[[#This Row],[Category]:[Category]],operations[[Month]:[Month]],summary17[[#Headers],[7]])} -> 0 | J9: {=SUMIFS(operations[[Amount]:[Amount]],operations[[Category]:[Category]],summary17[[#This Row],[Category]:[Category]],operations[[Month]:[Month]],summary17[[#Headers],[8]])} -> 0 | K9: {=SUMIFS(operations[[Amount]:[Amount]],operations[[Category]:[Category]],summary17[[#This Row],[Category]:[Category]],operations[[Month]:[Month]],summary17[[#Headers],[9]])} -> 0 | L9: {=SUMIFS(operations[[Amount]:[Amount]],operations[[Category]:[Category]],summary17[[#This Row],[Category]:[Category]],operations[[Month]:[Month]],summary17[[#Headers],[10]])} -> 0 | M9: {=SUMIFS(operations[[Amount]:[Amount]],operations[[Category]:[Category]],summary17[[#This Row],[Category]:[Category]],operations[[Month]:[Month]],summary17[[#Headers],[11]])} -> 0 | N9: {=SUMIFS(operations[[Amount]:[Amount]],operations[[Category]:[Category]],summary17[[#This Row],[Category]:[Category]],operations[[Month]:[Month]],summary17[[#Headers],[12]])} -> 0
A10: Total | C10: 2940.5 | D10: 845.5 | E10: 3786 | F10: {=SUMIFS(operations[[Amount]:[Amount]],operations[[Category]:[Category]],summary17[[#This Row],[Category]:[Category]],operations[[Month]:[Month]],summary17[[#Headers],[4]])} -> 0 | G10: {=SUMIFS(operations[[Amount]:[Amount]],operations[[Category]:[Category]],summary17[[#This Row],[Category]:[Category]],operations[[Month]:[Month]],summary17[[#Headers],[5]])} -> 0 | H10: {=SUMIFS(operations[[Amount]:[Amount]],operations[[Category]:[Category]],summary17[[#This Row],[Category]:[Category]],operations[[Month]:[Month]],summary17[[#Headers],[6]])} -> 0 | I10: {=SUMIFS(operations[[Amount]:[Amount]],operations[[Category]:[Category]],summary17[[#This Row],[Category]:[Category]],operations[[Month]:[Month]],summary17[[#Headers],[7]])} -> 0 | J10: {=SUMIFS(operations[[Amount]:[Amount]],operations[[Category]:[Category]],summary17[[#This Row],[Category]:[Category]],operations[[Month]:[Month]],summary17[[#Headers],[8]])} -> 0 | K10: {=SUMIFS(operations[[Amount]:[Amount]],operations[[Category]:[Category]],summary17[[#This Row],[Category]:[Category]],operations[[Month]:[Month]],summary17[[#Headers],[9]])} -> 0 | L10: {=SUMIFS(operations[[Amount]:[Amount]],operations[[Category]:[Category]],summary17[[#This Row],[Category]:[Category]],operations[[Month]:[Month]],summary17[[#Headers],[10]])} -> 0 | M10: {=SUMIFS(operations[[Amount]:[Amount]],operations[[Category]:[Category]],summary17[[#This Row],[Category]:[Category]],operations[[Month]:[Month]],summary17[[#Headers],[11]])} -> 0 | N10: {=SUMIFS(operations[[Amount]:[Amount]],operations[[Category]:[Category]],summary17[[#This Row],[Category]:[Category]],operations[[Month]:[Month]],summary17[[#Headers],[12]])} -> 0
A11: Allowance | B11: Income | C11: {=SUMIFS(operations[[Amount]:[Amount]],operations[[Category]:[Category]],summary17[[#This Row],[Category]:[Category]],operations[[Month]:[Month]],summary17[[#Headers],[1]])} -> 250 | D11: {=SUMIFS(operations[[Amount]:[Amount]],operations[[Category]:[Category]],summary17[[#This Row],[Category]:[Category]],operations[[Month]:[Month]],summary17[[#Headers],[2]])} -> 0 | E11: {=SUMIFS(operations[[Amount]:[Amount]],operations[[Category]:[Category]],summary17[[#This Row],[Category]:[Category]],operations[[Month]:[Month]],summary17[[#Headers],[3]])} -> 0 | F11: {=SUMIFS(operations[[Amount]:[Amount]],operations[[Category]:[Category]],summary17[[#This Row],[Category]:[Category]],operations[[Month]:[Month]],summary17[[#Headers],[4]])} -> 0 | G11: {=SUMIFS(operations[[Amount]:[Amount]],operations[[Category]:[Category]],summary17[[#This Row],[Category]:[Category]],operations[[Month]:[Month]],summary17[[#Headers],[5]])} -> 0 | H11: {=SUMIFS(operations[[Amount]:[Amount]],operations[[Category]:[Category]],summary17[[#This Row],[Category]:[Category]],operations[[Month]:[Month]],summary17[[#Headers],[6]])} -> 400 | I11: {=SUMIFS(operations[[Amount]:[Amount]],operations[[Category]:[Category]],summary17[[#This Row],[Category]:[Category]],operations[[Month]:[Month]],summary17[[#Headers],[7]])} -> 0 | J11: {=SUMIFS(operations[[Amount]:[Amount]],operations[[Category]:[Category]],summary17[[#This Row],[Category]:[Category]],operations[[Month]:[Month]],summary17[[#Headers],[8]])} -> 0 | K11: {=SUMIFS(operations[[Amount]:[Amount]],operations[[Category]:[Category]],summary17[[#This Row],[Category]:[Category]],operations[[Month]:[Month]],summary17[[#Headers],[9]])} -> 0 | L11: {=SUMIFS(operations[[Amount]:[Amount]],operations[[Category]:[Category]],summary17[[#This Row],[Category]:[Category]],operations[[Month]:[Month]],summary17[[#Headers],[10]])} -> 0 | M11: {=SUMIFS(operations[[Amount]:[Amount]],operations[[Category]:[Category]],summary17[[#This Row],[Category]:[Category]],operations[[Month]:[Month]],summary17[[#Headers],[11]])} -> 0 | N11: {=SUMIFS(operations[[Amount]:[Amount]],operations[[Category]:[Category]],summary17[[#This Row],[Category]:[Category]],operations[[Month]:[Month]],summary17[[#Headers],[12]])} -> 0
A12: Financial | B12: Income | C12: {=SUMIFS(operations[[Amount]:[Amount]],operations[[Category]:[Category]],summary17[[#This Row],[Category]:[Category]],operations[[Month]:[Month]],summary17[[#Headers],[1]])} -> 105.5 | D12: {=SUMIFS(operations[[Amount]:[Amount]],operations[[Category]:[Category]],summary17[[#This Row],[Category]:[Category]],operations[[Month]:[Month]],summary17[[#Headers],[2]])} -> 115 | E12: {=SUMIFS(operations[[Amount]:[Amount]],operations[[Category]:[Category]],summary17[[#This Row],[Category]:[Category]],operations[[Month]:[Month]],summary17[[#Headers],[3]])} -> 150 | F12: {=SUMIFS(operations[[Amount]:[Amount]],operations[[Category]:[Category]],summary17[[#This Row],[Category]:[Category]],operations[[Month]:[Month]],summary17[[#Headers],[4]])} -> 150 | G12: {=SUMIFS(operations[[Amount]:[Amount]],operations[[Category]:[Category]],summary17[[#This Row],[Category]:[Category]],operations[[Month]:[Month]],summary17[[#Headers],[5]])} -> 0 | H12: {=SUMIFS(operations[[Amount]:[Amount]],operations[[Category]:[Category]],summary17[[#This Row],[Category]:[Category]],operations[[Month]:[Month]],summary17[[#Headers],[6]])} -> 0 | I12: {=SUMIFS(operations[[Amount]:[Amount]],operations[[Category]:[Category]],summary17[[#This Row],[Category]:[Category]],operations[[Month]:[Month]],summary17[[#Headers],[7]])} -> 120 | J12: {=SUMIFS(operations[[Amount]:[Amount]],operations[[Category]:[Category]],summary17[[#This Row],[Category]:[Category]],operations[[Month]:[Month]],summary17[[#Headers],[8]])} -> 0 | K12: {=SUMIFS(operations[[Amount]:[Amount]],operations[[Category]:[Category]],summary17[[#This Row],[Category]:[Category]],operations[[Month]:[Month]],summary17[[#Headers],[9]])} -> 0 | L12: {=SUMIFS(operations[[Amount]:[Amount]],operations[[Category]:[Category]],summary17[[#This Row],[Category]:[Category]],operations[[Month]:[Month]],summary17[[#Headers],[10]])} -> 0 | M12: {=SUMIFS(operations[[Amount]:[Amount]],operations[[Category]:[Category]],summary17[[#This Row],[Category]:[Category]],operations[[Month]:[Month]],summary17[[#Headers],[11]])} -> 0 | N12: {=SUMIFS(operations[[Amount]:[Amount]],operations[[Category]:[Category]],summary17[[#This Row],[Category]:[Category]],operations[[Month]:[Month]],summary17[[#Headers],[12]])} -> 0
A13: Gift | B13: Income | C13: {=SUMIFS(operations[[Amount]:[Amount]],operations[[Category]:[Category]],summary17[[#This Row],[Category]:[Category]],operations[[Month]:[Month]],summary17[[#Headers],[1]])} -> 0 | D13: {=SUMIFS(operations[[Amount]:[Amount]],operations[[Category]:[Category]],summary17[[#This Row],[Category]:[Category]],operations[[Month]:[Month]],summary17[[#Headers],[2]])} -> 0 | E13: {=SUMIFS(operations[[Amount]:[Amount]],operations[[Category]:[Category]],summary17[[#This Row],[Category]:[Category]],operations[[Month]:[Month]],summary17[[#Headers],[3]])} -> 5 | F13: {=SUMIFS(operations[[Amount]:[Amount]],operations[[Category]:[Category]],summary17[[#This Row],[Category]:[Category]],operations[[Month]:[Month]],summary17[[#Headers],[4]])} -> 50 | G13: {=SUMIFS(operations[[Amount]:[Amount]],operations[[Category]:[Category]],summary17[[#This Row],[Category]:[Category]],operations[[Month]:[Month]],summary17[[#Headers],[5]])} -> 0 | H13: {=SUMIFS(operations[[Amount]:[Amount]],operations[[Category]:[Category]],summary17[[#This Row],[Category]:[Category]],operations[[Month]:[Month]],summary17[[#Headers],[6]])} -> 0 | I13: {=SUMIFS(operations[[Amount]:[Amount]],operations[[Category]:[Category]],summary17[[#This Row],[Category]:[Category]],operations[[Month]:[Month]],summary17[[#Headers],[7]])} -> 800 | J13: {=SUMIFS(operations[[Amount]:[Amount]],operations[[Category]:[Category]],summary17[[#This Row],[Category]:[Category]],operations[[Month]:[Month]],summary17[[#Headers],[8]])} -> 400 | K13: {=SUMIFS(operations[[Amount]:[Amount]],operations[[Category]:[Category]],summary17[[#This Row],[Category]:[Category]],operations[[Month]:[Month]],summary17[[#Headers],[9]])} -> 0 | L13: {=SUMIFS(operations[[Amount]:[Amount]],operations[[Category]:[Category]],summary17[[#This Row],[Category]:[Category]],operations[[Month]:[Month]],summary17[[#Headers],[10]])} -> 0 | M13: {=SUMIFS(operations[[Amount]:[Amount]],operations[[Category]:[Category]],summary17[[#This Row],[Category]:[Category]],operations[[Month]:[Month]],summary17[[#Headers],[11]])} -> 400 | N13: {=SUMIFS(operations[[Amount]:[Amount]],operations[[Category]:[Category]],summary17[[#This Row],[Category]:[Category]],operations[[Month]:[Month]],summary17[[#Headers],[12]])} -> 2000
A14: Other incoms | B14: Income | C14: {=SUMIFS(operations[[Amount]:[Amount]],operations[[Category]:[Category]],summary17[[#This Row],[Category]:[Category]],operations[[Month]:[Month]],summary17[[#Headers],[1]])} -> 800 | D14: {=SUMIFS(operations[[Amount]:[Amount]],operations[[Category]:[Category]],summary17[[#This Row],[Category]:[Category]],operations[[Month]:[Month]],summary17[[#Headers],[2]])} -> 1950 | E14: {=SUMIFS(operations[[Amount]:[Amount]],operations[[Category]:[Category]],summary17[[#This Row],[Category]:[Category]],operations[[Month]:[Month]],summary17[[#Headers],[3]])} -> 0 | F14: {=SUMIFS(operations[[Amount]:[Amount]],operations[[Category]:[Category]],summary17[[#This Row],[Category]:[Category]],operations[[Month]:[Month]],summary17[[#Headers],[4]])} -> 0 | G14: {=SUMIFS(operations[[Amount]:[Amount]],operations[[Category]:[Category]],summary17[[#This Row],[Category]:[Category]],operations[[Month]:[Month]],summary17[[#Headers],[5]])} -> 0 | H14: {=SUMIFS(operations[[Amount]:[Amount]],operations[[Category]:[Category]],summary17[[#This Row],[Category]:[Category]],operations[[Month]:[Month]],summary17[[#Headers],[6]])} -> 0 | I14: {=SUMIFS(operations[[Amount]:[Amount]],operations[[Category]:[Category]],summary17[[#This Row],[Category]:[Category]],operations[[Month]:[Month]],summary17[[#Headers],[7]])} -> 0 | J14: {=SUMIFS(operations[[Amount]:[Amount]],operations[[Category]:[Category]],summary17[[#This Row],[Category]:[Category]],operations[[Month]:[Month]],summary17[[#Headers],[8]])} -> 0 | K14: {=SUMIFS(operations[[Amount]:[Amount]],operations[[Category]:[Category]],summary17[[#This Row],[Category]:[Category]],operations[[Month]:[Month]],summary17[[#Headers],[9]])} -> 0 | L14: {=SUMIFS(operations[[Amount]:[Amount]],operations[[Category]:[Category]],summary17[[#This Row],[Category]:[Category]],operations[[Month]:[Month]],summary17[[#Headers],[10]])} -> 0 | M14: {=SUMIFS(operations[[Amount]:[Amount]],operations[[Category]:[Category]],summary17[[#This Row],[Category]:[Category]],operations[[Month]:[Month]],summary17[[#Headers],[11]])} -> 0 | N14: =SUBTOTAL(109,summary17[12]) -> -405
A15: Salary | B15: Income | C15: {=SUMIFS(operations[[Amount]:[Amount]],operations[[Category]:[Category]],summary17[[#This Row],[Category]:[Category]],operations[[Month]:[Month]],summary17[[#Headers],[1]])} -> 4500 | D15: {=SUMIFS(operations[[Amount]:[Amount]],operations[[Category]:[Category]],summary17[[#This Row],[Category]:[Category]],operations[[Month]:[Month]],summary17[[#Headers],[2]])} -> 4500 | E15: {=SUMIFS(operations[[Amount]:[Amount]],operations[[Category]:[Category]],summary17[[#This Row],[Category]:[Category]],operations[[Month]:[Month]],summary17[[#Headers],[3]])} -> 4500 | F15: {=SUMIFS(operations[[Amount]:[Amount]],operations[[Category]:[Category]],summary17[[#This Row],[Category]:[Category]],operations[[Month]:[Month]],summary17[[#Headers],[4]])} -> 4500 | G15: {=SUMIFS(operations[[Amount]:[Amount]],operations[[Category]:[Category]],summary17[[#This Row],[Category]:[Category]],operations[[Month]:[Month]],summary17[[#Headers],[5]])} -> 4500 | H15: {=SUMIFS(operations[[Amount]:[Amount]],operations[[Category]:[Category]],summary17[[#This Row],[Category]:[Category]],operations[[Month]:[Month]],summary17[[#Headers],[6]])} -> 4500 | I15: {=SUMIFS(operations[[Amount]:[Amount]],operations[[Category]:[Category]],summary17[[#This Row],[Category]:[Category]],operations[[Month]:[Month]],summary17[[#Headers],[7]])} -> 4500 | J15: {=SUMIFS(operations[[Amount]:[Amount]],operations[[Category]:[Category]],summary17[[#This Row],[Category]:[Category]],operations[[Month]:[Month]],summary17[[#Headers],[8]])} -> 4500 | K15: {=SUMIFS(operations[[Amount]:[Amount]],operations[[Category]:[Category]],summary17[[#This Row],[Category]:[Category]],operations[[Month]:[Month]],summary17[[#Headers],[9]])} -> 4500 | L15: {=SUMIFS(operations[[Amount]:[Amount]],operations[[Category]:[Category]],summary17[[#This Row],[Category]:[Category]],operations[[Month]:[Month]],summary17[[#Headers],[10]])} -> 4500 | M15: {=SUMIFS(operations[[Amount]:[Amount]],operations[[Category]:[Category]],summary17[[#This Row],[Category]:[Category]],operations[[Month]:[Month]],summary17[[#Headers],[11]])} -> 4500 | N15: =SUBTOTAL(109,summary17[12]) -> -405
A16: Scholarship | B16: Income | C16: {=SUMIFS(operations[[Amount]:[Amount]],operations[[Category]:[Category]],summary17[[#This Row],[Category]:[Category]],operations[[Month]:[Month]],summary17[[#Headers],[1]])} -> 0 | D16: {=SUMIFS(operations[[Amount]:[Amount]],operations[[Category]:[Category]],summary17[[#This Row],[Category]:[Category]],operations[[Month]:[Month]],summary17[[#Headers],[2]])} -> 0 | E16: {=SUMIFS(operations[[Amount]:[Amount]],operations[[Category]:[Category]],summary17[[#This Row],[Category]:[Category]],operations[[Month]:[Month]],summary17[[#Headers],[3]])} -> 0 | F16: {=SUMIFS(operations[[Amount]:[Amount]],operations[[Category]:[Category]],summary17[[#This Row],[Category]:[Category]],operations[[Month]:[Month]],summary17[[#Headers],[4]])} -> 0 | G16: {=SUMIFS(operations[[Amount]:[Amount]],operations[[Category]:[Category]],summary17[[#This Row],[Category]:[Category]],operations[[Month]:[Month]],summary17[[#Headers],[5]])} -> 0 | H16: {=SUMIFS(operations[[Amount]:[Amount]],operations[[Category]:[Category]],summary17[[#This Row],[Category]:[Category]],operations[[Month]:[Month]],summary17[[#Headers],[6]])} -> 0 | I16: {=SUMIFS(operations[[Amount]:[Amount]],operations[[Category]:[Category]],summary17[[#This Row],[Category]:[Category]],operations[[Month]:[Month]],summary17[[#Headers],[7]])} -> 500 | J16: {=SUMIFS(operations[[Amount]:[Amount]],operations[[Category]:[Category]],summary17[[#This Row],[Category]:[Category]],operations[[Month]:[Month]],summary17[[#Headers],[8]])} -> 500 | K16: {=SUMIFS(operations[[Amount]:[Amount]],operations[[Category]:[Category]],summary17[[#This Row],[Category]:[Category]],operations[[Month]:[Month]],summary17[[#Headers],[9]])} -> 0 | L16: {=SUMIFS(operations[[Amount]:[Amount]],operations[[Category]:[Category]],summary17[[#This Row],[Category]:[Category]],operations[[Month]:[Month]],summary17[[#Headers],[10]])} -> 0 | M16: {=SUMIFS(operations[[Amount]:[Amount]],operations[[Category]:[Category]],summary17[[#This Row],[Category]:[Category]],operations[[Month]:[Month]],summary17[[#Headers],[11]])} -> 0 | N16: =SUBTOTAL(109,summary17[12]) -> -405
A17: Transfer | B17: Transfer | C17: {=SUMIFS(operations[[Amount]:[Amount]],operations[[Category]:[Category]],summary17[[#This Row],[Category]:[Category]],operations[[Month]:[Month]],summary17[[#Headers],[1]])} -> 0 | D17: {=SUMIFS(operations[[Amount]:[Amount]],operations[[Category]:[Category]],summary17[[#This Row],[Category]:[Category]],operations[[Month]:[Month]],summary17[[#Headers],[2]])} -> 0 | E17: {=SUMIFS(operations[[Amount]:[Amount]],operations[[Category]:[Category]],summary17[[#This Row],[Category]:[Category]],operations[[Month]:[Month]],summary17[[#Headers],[3]])} -> 0 | F17: {=SUMIFS(operations[[Amount]:[Amount]],operations[[Category]:[Category]],summary17[[#This Row],[Category]:[Category]],operations[[Month]:[Month]],summary17[[#Headers],[4]])} -> 0 | G17: {=SUMIFS(operations[[Amount]:[Amount]],operations[[Category]:[Category]],summary17[[#This Row],[Category]:[Category]],operations[[Month]:[Month]],summary17[[#Headers],[5]])} -> 0 | H17: {=SUMIFS(operations[[Amount]:[Amount]],operations[[Category]:[Category]],summary17[[#This Row],[Category]:[Category]],operations[[Month]:[Month]],summary17[[#Headers],[6]])} -> 0 | I17: {=SUMIFS(operations[[Amount]:[Amount]],operations[[Category]:[Category]],summary17[[#This Row],[Category]:[Category]],operations[[Month]:[Month]],summary17[[#Headers],[7]])} -> 0 | J17: {=SUMIFS(operations[[Amount]:[Amount]],operations[[Category]:[Category]],summary17[[#This Row],[Category]:[Category]],operations[[Month]:[Month]],summary17[[#Headers],[8]])} -> -1020 | K17: {=SUMIFS(operations[[Amount]:[Amount]],operations[[Category]:[Category]],summary17[[#This Row],[Category]:[Category]],operations[[Month]:[Month]],summary17[[#Headers],[9]])} -> 0 | L17: {=SUMIFS(operations[[Amount]:[Amount]],operations[[Category]:[Category]],summary17[[#This Row],[Category]:[Category]],operations[[Month]:[Month]],summary17[[#Headers],[10]])} -> 0 | M17: {=SUMIFS(operations[[Amount]:[Amount]],operations[[Category]:[Category]],summary17[[#This Row],[Category]:[Category]],operations[[Month]:[Month]],summary17[[#Headers],[11]])} -> 0 | N17: =SUBTOTAL(109,summary17[12]) -> -405
A18: Total | C18: =SUBTOTAL(109,summary17[1]) -> 11536.5 | D18: =SUBTOTAL(109,summary17[2]) -> 8256 | E18: =SUBTOTAL(109,summary17[3]) -> 12227 | F18: =SUBTOTAL(109,summary17[4]) -> 4700 | G18: =SUBTOTAL(109,summary17[5]) -> 4500 | H18: =SUBTOTAL(109,summary17[6]) -> 4900 | I18: =SUBTOTAL(109,summary17[7]) -> 5920 | J18: =SUBTOTAL(109,summary17[8]) -> 4380 | K18: =SUBTOTAL(109,summary17[9]) -> 4500 | L18: =SUBTOTAL(109,summary17[10]) -> 4500 | M18: =SUBTOTAL(109,summary17[11]) -> 4900 | N18: =SUBTOTAL(109,summary17[12]) -> -405

Sheet 12
A1: Bank | B1: Product | C1: Opening balance | D1: Operation | E1: Closing balance | G1: Category | H1: Total | J1: Category | K1: Total | N1: Type
A2: Millennium | B2: Account | C2: {=INDIRECT("raport_"&$B$12-1&"[@[Closing balance ]]")} -> #REF! | D2: =SUMIFS(operations[Amount],operations[Bank],raports_12[[#This Row],[Bank]],operations[Product],raports_12[[#This Row],[Product]],operations[Month],$B$12) -> 0 | E2: =raports_12[[#This Row],[Opening balance]]+raports_12[[#This Row],[Operation]] -> #REF! | G2: Accomodation | H2: =SUMIFS(operations[Amount],operations[Category],Expenses12[[#This Row],[Category]],operations[Month],'1'!$B$12) -> -2000 | J2: Other expences | N2: Expense
A3: Millennium | B3: Savings account | C3: 10.5 | D3: =SUMIFS(operations[Amount],operations[Bank],raports_12[[#This Row],[Bank]],operations[Product],raports_12[[#This Row],[Product]],operations[Month],$B$12) -> 0 | E3: =raports_12[[#This Row],[Opening balance]]+raports_12[[#This Row],[Operation]] -> 10.5 | G3: Clothing | H3: =SUMIFS(operations[Amount],operations[Category],Expenses12[[#This Row],[Category]],operations[Month],'1'!$B$12) -> -80 | J3: Studies | K3: =SUMIFS(operations[Amount],operations[Category],Table916283236404448525660[[#This Row],[Category]],operations[Month],'1'!$B$12) -> -100 | N3: Expense
A4: Santander | B4: Account | C4: 600 | D4: =SUMIFS(operations[Amount],operations[Bank],raports_12[[#This Row],[Bank]],operations[Product],raports_12[[#This Row],[Product]],operations[Month],$B$12) -> 1320 | E4: =raports_12[[#This Row],[Opening balance]]+raports_12[[#This Row],[Operation]] -> 1920 | G4: Entertainment | H4: =SUMIFS(operations[Amount],operations[Category],Expenses12[[#This Row],[Category]],operations[Month],'1'!$B$12) -> -85 | J4: Transportation | K4: =SUMIFS(operations[Amount],operations[Category],Table916283236404448525660[[#This Row],[Category]],operations[Month],'1'!$B$12) -> -80 | N4: Expense
A5: Santander | B5: Credit card | C5: 0 | D5: =SUMIFS(operations[Amount],operations[Bank],raports_12[[#This Row],[Bank]],operations[Product],raports_12[[#This Row],[Product]],operations[Month],$B$12) -> 0 | E5: =raports_12[[#This Row],[Opening balance]]+raports_12[[#This Row],[Operation]] -> 0 | G5: Groceries | H5: =SUMIFS(operations[Amount],operations[Category],Expenses12[[#This Row],[Category]],operations[Month],'1'!$B$12) -> -1715 | J5: Allowance | K5: =SUMIFS(operations[Amount],operations[Category],Table916283236404448525660[[#This Row],[Category]],operations[Month],'1'!$B$12) -> 250 | N5: Expense
A6: Santander | B6: Fixed-term deposit | C6: 2000 | D6: =SUMIFS(operations[Amount],operations[Bank],raports_12[[#This Row],[Bank]],operations[Product],raports_12[[#This Row],[Product]],operations[Month],$B$12) -> 0 | E6: =raports_12[[#This Row],[Opening balance]]+raports_12[[#This Row],[Operation]] -> 2000 | G6: Health&Beauty | H6: =SUMIFS(operations[Amount],operations[Category],Expenses12[[#This Row],[Category]],operations[Month],'1'!$B$12) -> -100 | J6: Financial | K6: =SUMIFS(operations[Amount],operations[Category],Table916283236404448525660[[#This Row],[Category]],operations[Month],'1'!$B$12) -> 105.5 | N6: Expense
A7: Wallet | B7: Gift card | C7: 200 | D7: =SUMIFS(operations[Amount],operations[Bank],raports_12[[#This Row],[Bank]],operations[Product],raports_12[[#This Row],[Product]],operations[Month],$B$12) -> 0 | E7: =raports_12[[#This Row],[Opening balance]]+raports_12[[#This Row],[Operation]] -> 200 | G7: Multimedia | H7: =SUMIFS(operations[Amount],operations[Category],Expenses12[[#This Row],[Category]],operations[Month],'1'!$B$12) -> -150 | J7: Gift | K7: =SUMIFS(operations[Amount],operations[Category],Table916283236404448525660[[#This Row],[Category]],operations[Month],'1'!$B$12) -> 0 | N7: Expense
A8: Wallet | B8: Money | C8: 30 | D8: =SUMIFS(operations[Amount],operations[Bank],raports_12[[#This Row],[Bank]],operations[Product],raports_12[[#This Row],[Product]],operations[Month],$B$12) -> 1100 | E8: =raports_12[[#This Row],[Opening balance]]+raports_12[[#This Row],[Operation]] -> 1130 | G8: Total | H8: =SUBTOTAL(109,Expenses12[Total]) -> -4130 | J8: Other incoms | K8: =SUMIFS(operations[Amount],operations[Category],Table916283236404448525660[[#This Row],[Category]],operations[Month],'1'!$B$12) -> 800 | N8: Expense
A9: Total | C9: =SUBTOTAL(109,raports_12[Opening balance]) -> #REF! | D9: =SUBTOTAL(109,raports_12[Operation]) -> 2420 | E9: =SUBTOTAL(109,raports_12[Closing balance]) -> #REF! | J9: Salary | K9: =SUMIFS(operations[Amount],operations[Category],Table916283236404448525660[[#This Row],[Category]],operations[Month],'1'!$B$12) -> 4500 | N9: Expense
J10: Scholarship | K10: =SUMIFS(operations[Amount],operations[Category],Table916283236404448525660[[#This Row],[Category]],operations[Month],'1'!$B$12) -> 0 | N10: Expense
J11: Transfer | K11: =SUMIFS(operations[Amount],operations[Category],Table916283236404448525660[[#This Row],[Category]],operations[Month],'1'!$B$12) -> 0 | N11: Income
A12: Month | B12: {=_xlfn.TEXTAFTER(CELL("filename",A1),"]")} -> 12 | J12: Total | K12: =SUBTOTAL(109,Table916283236404448525660[Total]) -> 5475.5 | N12: Income
N13: Income
A14: Type | B14: Total | N14: Income
A15: Income | B15: =SUMIFS(operations[Amount],operations[Type],balance_12[[#This Row],[Type]],operations[Month],'1'!$B$12) -> 5655.5 | N15: Income
A16: Expense | B16: =SUMIFS(operations[Amount],operations[Type],balance_12[[#This Row],[Type]],operations[Month],'1'!$B$12) -> -4810 | N16: Income
A17: Transfer | B17: =SUMIFS(operations[Amount],operations[Type],balance_12[[#This Row],[Type]],operations[Month],'1'!$B$12) -> 0 | N17: Transfer
A18: Total | B18: =SUBTOTAL(109,balance_12[Total]) -> 845.5

Sheet 11
A1: Bank | B1: Product | C1: Opening balance | D1: Operation | E1: Closing balance | G1: Category | H1: Total | J1: Category | K1: Total | N1: Type
A2: Millennium | B2: Account | C2: {=INDIRECT("raport_"&$B$12-1&"[@[Closing balance ]]")} -> #REF! | D2: =SUMIFS(operations[Amount],operations[Bank],raports_11[[#This Row],[Bank]],operations[Product],raports_11[[#This Row],[Product]],operations[Month],$B$12) -> 0 | E2: =raports_11[[#This Row],[Opening balance]]+raports_11[[#This Row],[Operation]] -> #REF! | G2: Accomodation | H2: =SUMIFS(operations[Amount],operations[Category],Expenses11[[#This Row],[Category]],operations[Month],'1'!$B$12) -> -2000 | J2: Other expences | N2: Expense
A3: Millennium | B3: Savings account | C3: 10.5 | D3: =SUMIFS(operations[Amount],operations[Bank],raports_11[[#This Row],[Bank]],operations[Product],raports_11[[#This Row],[Product]],operations[Month],$B$12) -> 0 | E3: =raports_11[[#This Row],[Opening balance]]+raports_11[[#This Row],[Operation]] -> 10.5 | G3: Clothing | H3: =SUMIFS(operations[Amount],operations[Category],Expenses11[[#This Row],[Category]],operations[Month],'1'!$B$12) -> -80 | J3: Studies | K3: =SUMIFS(operations[Amount],operations[Category],Table9162832364044485256[[#This Row],[Category]],operations[Month],'1'!$B$12) -> -100 | N3: Expense
A4: Santander | B4: Account | C4: 600 | D4: =SUMIFS(operations[Amount],operations[Bank],raports_11[[#This Row],[Bank]],operations[Product],raports_11[[#This Row],[Product]],operations[Month],$B$12) -> 960 | E4: =raports_11[[#This Row],[Opening balance]]+raports_11[[#This Row],[Operation]] -> 1560 | G4: Entertainment | H4: =SUMIFS(operations[Amount],operations[Category],Expenses11[[#This Row],[Category]],operations[Month],'1'!$B$12) -> -85 | J4: Transportation | K4: =SUMIFS(operations[Amount],operations[Category],Table9162832364044485256[[#This Row],[Category]],operations[Month],'1'!$B$12) -> -80 | N4: Expense
A5: Santander | B5: Credit card | C5: 0 | D5: =SUMIFS(operations[Amount],operations[Bank],raports_11[[#This Row],[Bank]],operations[Product],raports_11[[#This Row],[Product]],operations[Month],$B$12) -> 40 | E5: =raports_11[[#This Row],[Opening balance]]+raports_11[[#This Row],[Operation]] -> 40 | G5: Groceries | H5: =SUMIFS(operations[Amount],operations[Category],Expenses11[[#This Row],[Category]],operations[Month],'1'!$B$12) -> -1715 | J5: Allowance | K5: =SUMIFS(operations[Amount],operations[Category],Table9162832364044485256[[#This Row],[Category]],operations[Month],'1'!$B$12) -> 250 | N5: Expense
A6: Santander | B6: Fixed-term deposit | C6: 2000 | D6: =SUMIFS(operations[Amount],operations[Bank],raports_11[[#This Row],[Bank]],operations[Product],raports_11[[#This Row],[Product]],operations[Month],$B$12) -> 0 | E6: =raports_11[[#This Row],[Opening balance]]+raports_11[[#This Row],[Operation]] -> 2000 | G6: Health&Beauty | H6: =SUMIFS(operations[Amount],operations[Category],Expenses11[[#This Row],[Category]],operations[Month],'1'!$B$12) -> -100 | J6: Financial | K6: =SUMIFS(operations[Amount],operations[Category],Table9162832364044485256[[#This Row],[Category]],operations[Month],'1'!$B$12) -> 105.5 | N6: Expense
A7: Wallet | B7: Gift card | C7: 200 | D7: =SUMIFS(operations[Amount],operations[Bank],raports_11[[#This Row],[Bank]],operations[Product],raports_11[[#This Row],[Product]],operations[Month],$B$12) -> 0 | E7: =raports_11[[#This Row],[Opening balance]]+raports_11[[#This Row],[Operation]] -> 200 | G7: Multimedia | H7: =SUMIFS(operations[Amount],operations[Category],Expenses11[[#This Row],[Category]],operations[Month],'1'!$B$12) -> -150 | J7: Gift | K7: =SUMIFS(operations[Amount],operations[Category],Table9162832364044485256[[#This Row],[Category]],operations[Month],'1'!$B$12) -> 0 | N7: Expense
A8: Wallet | B8: Money | C8: 30 | D8: =SUMIFS(operations[Amount],operations[Bank],raports_11[[#This Row],[Bank]],operations[Product],raports_11[[#This Row],[Product]],operations[Month],$B$12) -> 400 | E8: =raports_11[[#This Row],[Opening balance]]+raports_11[[#This Row],[Operation]] -> 430 | G8: Total | H8: =SUBTOTAL(109,Expenses11[Total]) -> -4130 | J8: Other incoms | K8: =SUMIFS(operations[Amount],operations[Category],Table9162832364044485256[[#This Row],[Category]],operations[Month],'1'!$B$12) -> 800 | N8: Expense
A9: Total | C9: =SUBTOTAL(109,raports_11[Opening balance]) -> #REF! | D9: =SUBTOTAL(109,raports_11[Operation]) -> 1400 | E9: =SUBTOTAL(109,raports_11[Closing balance]) -> #REF! | J9: Salary | K9: =SUMIFS(operations[Amount],operations[Category],Table9162832364044485256[[#This Row],[Category]],operations[Month],'1'!$B$12) -> 4500 | N9: Expense
J10: Scholarship | K10: =SUMIFS(operations[Amount],operations[Category],Table9162832364044485256[[#This Row],[Category]],operations[Month],'1'!$B$12) -> 0 | N10: Expense
J11: Transfer | K11: =SUMIFS(operations[Amount],operations[Category],Table9162832364044485256[[#This Row],[Category]],operations[Month],'1'!$B$12) -> 0 | N11: Income
A12: Month | B12: {=_xlfn.TEXTAFTER(CELL("filename",A1),"]")} -> 11 | J12: Total | K12: =SUBTOTAL(109,Table9162832364044485256[Total]) -> 5475.5 | N12: Income
N13: Income
A14: Type | B14: Total | N14: Income
A15: Income | B15: =SUMIFS(operations[Amount],operations[Type],balance_11[[#This Row],[Type]],operations[Month],'1'!$B$12) -> 5655.5 | N15: Income
A16: Expense | B16: =SUMIFS(operations[Amount],operations[Type],balance_11[[#This Row],[Type]],operations[Month],'1'!$B$12) -> -4810 | N16: Income
A17: Transfer | B17: =SUMIFS(operations[Amount],operations[Type],balance_11[[#This Row],[Type]],operations[Month],'1'!$B$12) -> 0 | N17: Transfer
A18: Total | B18: =SUBTOTAL(109,balance_11[Total]) -> 845.5

Sheet 9
A1: Bank | B1: Product | C1: Opening balance | D1: Operation | E1: Closing balance | G1: Category | H1: Total | J1: Category | K1: Total | N1: Type
A2: Millennium | B2: Account | C2: {=INDIRECT("raport_"&$B$12-1&"[@[Closing balance ]]")} -> #REF! | D2: =SUMIFS(operations[Amount],operations[Bank],raports_9[[#This Row],[Bank]],operations[Product],raports_9[[#This Row],[Product]],operations[Month],$B$12) -> -20 | E2: =raports_9[[#This Row],[Opening balance]]+raports_9[[#This Row],[Operation]] -> #REF! | G2: Accomodation | H2: =SUMIFS(operations[Amount],operations[Category],Expenses9[[#This Row],[Category]],operations[Month],'1'!$B$12) -> -2000 | J2: Other expences | N2: Expense
A3: Millennium | B3: Savings account | C3: 10.5 | D3: =SUMIFS(operations[Amount],operations[Bank],raports_9[[#This Row],[Bank]],operations[Product],raports_9[[#This Row],[Product]],operations[Month],$B$12) -> 0 | E3: =raports_9[[#This Row],[Opening balance]]+raports_9[[#This Row],[Operation]] -> 10.5 | G3: Clothing | H3: =SUMIFS(operations[Amount],operations[Category],Expenses9[[#This Row],[Category]],operations[Month],'1'!$B$12) -> -80 | J3: Studies | K3: =SUMIFS(operations[Amount],operations[Category],Table916283236404448[[#This Row],[Category]],operations[Month],'1'!$B$12) -> -100 | N3: Expense
A4: Santander | B4: Account | C4: 600 | D4: =SUMIFS(operations[Amount],operations[Bank],raports_9[[#This Row],[Bank]],operations[Product],raports_9[[#This Row],[Product]],operations[Month],$B$12) -> 1689.5 | E4: =raports_9[[#This Row],[Opening balance]]+raports_9[[#This Row],[Operation]] -> 2289.5 | G4: Entertainment | H4: =SUMIFS(operations[Amount],operations[Category],Expenses9[[#This Row],[Category]],operations[Month],'1'!$B$12) -> -85 | J4: Transportation | K4: =SUMIFS(operations[Amount],operations[Category],Table916283236404448[[#This Row],[Category]],operations[Month],'1'!$B$12) -> -80 | N4: Expense
A5: Santander | B5: Credit card | C5: 0 | D5: =SUMIFS(operations[Amount],operations[Bank],raports_9[[#This Row],[Bank]],operations[Product],raports_9[[#This Row],[Product]],operations[Month],$B$12) -> 82 | E5: =raports_9[[#This Row],[Opening balance]]+raports_9[[#This Row],[Operation]] -> 82 | G5: Groceries | H5: =SUMIFS(operations[Amount],operations[Category],Expenses9[[#This Row],[Category]],operations[Month],'1'!$B$12) -> -1715 | J5: Allowance | K5: =SUMIFS(operations[Amount],operations[Category],Table916283236404448[[#This Row],[Category]],operations[Month],'1'!$B$12) -> 250 | N5: Expense
A6: Santander | B6: Fixed-term deposit | C6: 2000 | D6: =SUMIFS(operations[Amount],operations[Bank],raports_9[[#This Row],[Bank]],operations[Product],raports_9[[#This Row],[Product]],operations[Month],$B$12) -> 0 | E6: =raports_9[[#This Row],[Opening balance]]+raports_9[[#This Row],[Operation]] -> 2000 | G6: Health&Beauty | H6: =SUMIFS(operations[Amount],operations[Category],Expenses9[[#This Row],[Category]],operations[Month],'1'!$B$12) -> -100 | J6: Financial | K6: =SUMIFS(operations[Amount],operations[Category],Table916283236404448[[#This Row],[Category]],operations[Month],'1'!$B$12) -> 105.5 | N6: Expense
A7: Wallet | B7: Gift card | C7: 200 | D7: =SUMIFS(operations[Amount],operations[Bank],raports_9[[#This Row],[Bank]],operations[Product],raports_9[[#This Row],[Product]],operations[Month],$B$12) -> 0 | E7: =raports_9[[#This Row],[Opening balance]]+raports_9[[#This Row],[Operation]] -> 200 | G7: Multimedia | H7: =SUMIFS(operations[Amount],operations[Category],Expenses9[[#This Row],[Category]],operations[Month],'1'!$B$12) -> -150 | J7: Gift | K7: =SUMIFS(operations[Amount],operations[Category],Table916283236404448[[#This Row],[Category]],operations[Month],'1'!$B$12) -> 0 | N7: Expense
A8: Wallet | B8: Money | C8: 30 | D8: =SUMIFS(operations[Amount],operations[Bank],raports_9[[#This Row],[Bank]],operations[Product],raports_9[[#This Row],[Product]],operations[Month],$B$12) -> 0 | E8: =raports_9[[#This Row],[Opening balance]]+raports_9[[#This Row],[Operation]] -> 30 | G8: Total | H8: =SUBTOTAL(109,Expenses9[Total]) -> -4130 | J8: Other incoms | K8: =SUMIFS(operations[Amount],operations[Category],Table916283236404448[[#This Row],[Category]],operations[Month],'1'!$B$12) -> 800 | N8: Expense
A9: Total | C9: =SUBTOTAL(109,raports_9[Opening balance]) -> #REF! | D9: =SUBTOTAL(109,raports_9[Operation]) -> 1751.5 | E9: =SUBTOTAL(109,raports_9[Closing balance]) -> #REF! | J9: Salary | K9: =SUMIFS(operations[Amount],operations[Category],Table916283236404448[[#This Row],[Category]],operations[Month],'1'!$B$12) -> 4500 | N9: Expense
J10: Scholarship | K10: =SUMIFS(operations[Amount],operations[Category],Table916283236404448[[#This Row],[Category]],operations[Month],'1'!$B$12) -> 0 | N10: Expense
J11: Transfer | K11: =SUMIFS(operations[Amount],operations[Category],Table916283236404448[[#This Row],[Category]],operations[Month],'1'!$B$12) -> 0 | N11: Income
A12: Month | B12: {=_xlfn.TEXTAFTER(CELL("filename",A1),"]")} -> 9 | J12: Total | K12: =SUBTOTAL(109,Table916283236404448[Total]) -> 5475.5 | N12: Income
N13: Income
A14: Type | B14: Total | N14: Income
A15: Income | B15: =SUMIFS(operations[Amount],operations[Type],balance_9[[#This Row],[Type]],operations[Month],'1'!$B$12) -> 5655.5 | N15: Income
A16: Expense | B16: =SUMIFS(operations[Amount],operations[Type],balance_9[[#This Row],[Type]],operations[Month],'1'!$B$12) -> -4810 | N16: Income
A17: Transfer | B17: =SUMIFS(operations[Amount],operations[Type],balance_9[[#This Row],[Type]],operations[Month],'1'!$B$12) -> 0 | N17: Transfer
A18: Total | B18: =SUBTOTAL(109,balance_9[Total]) -> 845.5

Sheet 10
A1: Bank | B1: Product | C1: Opening balance | D1: Operation | E1: Closing balance | G1: Category | H1: Total | J1: Category | K1: Total | N1: Type
A2: Millennium | B2: Account | C2: {=INDIRECT("raport_"&$B$12-1&"[@[Closing balance ]]")} -> #REF! | D2: =SUMIFS(operations[Amount],operations[Bank],raports_10[[#This Row],[Bank]],operations[Product],raports_10[[#This Row],[Product]],operations[Month],$B$12) -> 0 | E2: =raports_10[[#This Row],[Opening balance]]+raports_10[[#This Row],[Operation]] -> #REF! | G2: Accomodation | H2: =SUMIFS(operations[Amount],operations[Category],Expenses10[[#This Row],[Category]],operations[Month],'1'!$B$12) -> -2000 | J2: Other expences | N2: Expense
A3: Millennium | B3: Savings account | C3: 10.5 | D3: =SUMIFS(operations[Amount],operations[Bank],raports_10[[#This Row],[Bank]],operations[Product],raports_10[[#This Row],[Product]],operations[Month],$B$12) -> 0 | E3: =raports_10[[#This Row],[Opening balance]]+raports_10[[#This Row],[Operation]] -> 10.5 | G3: Clothing | H3: =SUMIFS(operations[Amount],operations[Category],Expenses10[[#This Row],[Category]],operations[Month],'1'!$B$12) -> -80 | J3: Studies | K3: =SUMIFS(operations[Amount],operations[Category],Table91628323640444852[[#This Row],[Category]],operations[Month],'1'!$B$12) -> -100 | N3: Expense
A4: Santander | B4: Account | C4: 600 | D4: =SUMIFS(operations[Amount],operations[Bank],raports_10[[#This Row],[Bank]],operations[Product],raports_10[[#This Row],[Product]],operations[Month],$B$12) -> 1690 | E4: =raports_10[[#This Row],[Opening balance]]+raports_10[[#This Row],[Operation]] -> 2290 | G4: Entertainment | H4: =SUMIFS(operations[Amount],operations[Category],Expenses10[[#This Row],[Category]],operations[Month],'1'!$B$12) -> -85 | J4: Transportation | K4: =SUMIFS(operations[Amount],operations[Category],Table91628323640444852[[#This Row],[Category]],operations[Month],'1'!$B$12) -> -80 | N4: Expense
A5: Santander | B5: Credit card | C5: 0 | D5: =SUMIFS(operations[Amount],operations[Bank],raports_10[[#This Row],[Bank]],operations[Product],raports_10[[#This Row],[Product]],operations[Month],$B$12) -> -20 | E5: =raports_10[[#This Row],[Opening balance]]+raports_10[[#This Row],[Operation]] -> -20 | G5: Groceries | H5: =SUMIFS(operations[Amount],operations[Category],Expenses10[[#This Row],[Category]],operations[Month],'1'!$B$12) -> -1715 | J5: Allowance | K5: =SUMIFS(operations[Amount],operations[Category],Table91628323640444852[[#This Row],[Category]],operations[Month],'1'!$B$12) -> 250 | N5: Expense
A6: Santander | B6: Fixed-term deposit | C6: 2000 | D6: =SUMIFS(operations[Amount],operations[Bank],raports_10[[#This Row],[Bank]],operations[Product],raports_10[[#This Row],[Product]],operations[Month],$B$12) -> 0 | E6: =raports_10[[#This Row],[Opening balance]]+raports_10[[#This Row],[Operation]] -> 2000 | G6: Health&Beauty | H6: =SUMIFS(operations[Amount],operations[Category],Expenses10[[#This Row],[Category]],operations[Month],'1'!$B$12) -> -100 | J6: Financial | K6: =SUMIFS(operations[Amount],operations[Category],Table91628323640444852[[#This Row],[Category]],operations[Month],'1'!$B$12) -> 105.5 | N6: Expense
A7: Wallet | B7: Gift card | C7: 200 | D7: =SUMIFS(operations[Amount],operations[Bank],raports_10[[#This Row],[Bank]],operations[Product],raports_10[[#This Row],[Product]],operations[Month],$B$12) -> 0 | E7: =raports_10[[#This Row],[Opening balance]]+raports_10[[#This Row],[Operation]] -> 200 | G7: Multimedia | H7: =SUMIFS(operations[Amount],operations[Category],Expenses10[[#This Row],[Category]],operations[Month],'1'!$B$12) -> -150 | J7: Gift | K7: =SUMIFS(operations[Amount],operations[Category],Table91628323640444852[[#This Row],[Category]],operations[Month],'1'!$B$12) -> 0 | N7: Expense
A8: Wallet | B8: Money | C8: 30 | D8: =SUMIFS(operations[Amount],operations[Bank],raports_10[[#This Row],[Bank]],operations[Product],raports_10[[#This Row],[Product]],operations[Month],$B$12) -> 0 | E8: =raports_10[[#This Row],[Opening balance]]+raports_10[[#This Row],[Operation]] -> 30 | G8: Total | H8: =SUBTOTAL(109,Expenses10[Total]) -> -4130 | J8: Other incoms | K8: =SUMIFS(operations[Amount],operations[Category],Table91628323640444852[[#This Row],[Category]],operations[Month],'1'!$B$12) -> 800 | N8: Expense
A9: Total | C9: =SUBTOTAL(109,raports_10[Opening balance]) -> #REF! | D9: =SUBTOTAL(109,raports_10[Operation]) -> 1670 | E9: =SUBTOTAL(109,raports_10[Closing balance]) -> #REF! | J9: Salary | K9: =SUMIFS(operations[Amount],operations[Category],Table91628323640444852[[#This Row],[Category]],operations[Month],'1'!$B$12) -> 4500 | N9: Expense
J10: Scholarship | K10: =SUMIFS(operations[Amount],operations[Category],Table91628323640444852[[#This Row],[Category]],operations[Month],'1'!$B$12) -> 0 | N10: Expense
J11: Transfer | K11: =SUMIFS(operations[Amount],operations[Category],Table91628323640444852[[#This Row],[Category]],operations[Month],'1'!$B$12) -> 0 | N11: Income
A12: Month | B12: {=_xlfn.TEXTAFTER(CELL("filename",A1),"]")} -> 10 | J12: Total | K12: =SUBTOTAL(109,Table91628323640444852[Total]) -> 5475.5 | N12: Income
N13: Income
A14: Type | B14: Total | N14: Income
A15: Income | B15: =SUMIFS(operations[Amount],operations[Type],balance_10[[#This Row],[Type]],operations[Month],'1'!$B$12) -> 5655.5 | N15: Income
A16: Expense | B16: =SUMIFS(operations[Amount],operations[Type],balance_10[[#This Row],[Type]],operations[Month],'1'!$B$12) -> -4810 | N16: Income
A17: Transfer | B17: =SUMIFS(operations[Amount],operations[Type],balance_10[[#This Row],[Type]],operations[Month],'1'!$B$12) -> 0 | N17: Transfer
A18: Total | B18: =SUBTOTAL(109,balance_10[Total]) -> 845.5

Sheet 8
A1: Bank | B1: Product | C1: Opening balance | D1: Operation | E1: Closing balance | G1: Category | H1: Total | J1: Category | K1: Total | N1: Type
A2: Millennium | B2: Account | C2: {=INDIRECT("raport_"&$B$12-1&"[@[Closing balance ]]")} -> #REF! | D2: =SUMIFS(operations[Amount],operations[Bank],raports_8[[#This Row],[Bank]],operations[Product],raports_8[[#This Row],[Product]],operations[Month],$B$12) -> 200 | E2: =raports_8[[#This Row],[Opening balance]]+raports_8[[#This Row],[Operation]] -> #REF! | G2: Accomodation | H2: =SUMIFS(operations[Amount],operations[Category],Expenses8[[#This Row],[Category]],operations[Month],'1'!$B$12) -> -2000 | J2: Other expences | N2: Expense
A3: Millennium | B3: Savings account | C3: 10.5 | D3: =SUMIFS(operations[Amount],operations[Bank],raports_8[[#This Row],[Bank]],operations[Product],raports_8[[#This Row],[Product]],operations[Month],$B$12) -> -300 | E3: =raports_8[[#This Row],[Opening balance]]+raports_8[[#This Row],[Operation]] -> -289.5 | G3: Clothing | H3: =SUMIFS(operations[Amount],operations[Category],Expenses8[[#This Row],[Category]],operations[Month],'1'!$B$12) -> -80 | J3: Studies | K3: =SUMIFS(operations[Amount],operations[Category],Table9162832364044[[#This Row],[Category]],operations[Month],'1'!$B$12) -> -100 | N3: Expense
A4: Santander | B4: Account | C4: 600 | D4: =SUMIFS(operations[Amount],operations[Bank],raports_8[[#This Row],[Bank]],operations[Product],raports_8[[#This Row],[Product]],operations[Month],$B$12) -> 1475 | E4: =raports_8[[#This Row],[Opening balance]]+raports_8[[#This Row],[Operation]] -> 2075 | G4: Entertainment | H4: =SUMIFS(operations[Amount],operations[Category],Expenses8[[#This Row],[Category]],operations[Month],'1'!$B$12) -> -85 | J4: Transportation | K4: =SUMIFS(operations[Amount],operations[Category],Table9162832364044[[#This Row],[Category]],operations[Month],'1'!$B$12) -> -80 | N4: Expense
A5: Santander | B5: Credit card | C5: 0 | D5: =SUMIFS(operations[Amount],operations[Bank],raports_8[[#This Row],[Bank]],operations[Product],raports_8[[#This Row],[Product]],operations[Month],$B$12) -> 33 | E5: =raports_8[[#This Row],[Opening balance]]+raports_8[[#This Row],[Operation]] -> 33 | G5: Groceries | H5: =SUMIFS(operations[Amount],operations[Category],Expenses8[[#This Row],[Category]],operations[Month],'1'!$B$12) -> -1715 | J5: Allowance | K5: =SUMIFS(operations[Amount],operations[Category],Table9162832364044[[#This Row],[Category]],operations[Month],'1'!$B$12) -> 250 | N5: Expense
A6: Santander | B6: Fixed-term deposit | C6: 2000 | D6: =SUMIFS(operations[Amount],operations[Bank],raports_8[[#This Row],[Bank]],operations[Product],raports_8[[#This Row],[Product]],operations[Month],$B$12) -> -1020 | E6: =raports_8[[#This Row],[Opening balance]]+raports_8[[#This Row],[Operation]] -> 980 | G6: Health&Beauty | H6: =SUMIFS(operations[Amount],operations[Category],Expenses8[[#This Row],[Category]],operations[Month],'1'!$B$12) -> -100 | J6: Financial | K6: =SUMIFS(operations[Amount],operations[Category],Table9162832364044[[#This Row],[Category]],operations[Month],'1'!$B$12) -> 105.5 | N6: Expense
A7: Wallet | B7: Gift card | C7: 200 | D7: =SUMIFS(operations[Amount],operations[Bank],raports_8[[#This Row],[Bank]],operations[Product],raports_8[[#This Row],[Product]],operations[Month],$B$12) -> 0 | E7: =raports_8[[#This Row],[Opening balance]]+raports_8[[#This Row],[Operation]] -> 200 | G7: Multimedia | H7: =SUMIFS(operations[Amount],operations[Category],Expenses8[[#This Row],[Category]],operations[Month],'1'!$B$12) -> -150 | J7: Gift | K7: =SUMIFS(operations[Amount],operations[Category],Table9162832364044[[#This Row],[Category]],operations[Month],'1'!$B$12) -> 0 | N7: Expense
A8: Wallet | B8: Money | C8: 30 | D8: =SUMIFS(operations[Amount],operations[Bank],raports_8[[#This Row],[Bank]],operations[Product],raports_8[[#This Row],[Product]],operations[Month],$B$12) -> 2.5 | E8: =raports_8[[#This Row],[Opening balance]]+raports_8[[#This Row],[Operation]] -> 32.5 | G8: Total | H8: =SUBTOTAL(109,Expenses8[Total]) -> -4130 | J8: Other incoms | K8: =SUMIFS(operations[Amount],operations[Category],Table9162832364044[[#This Row],[Category]],operations[Month],'1'!$B$12) -> 800 | N8: Expense
A9: Total | C9: =SUBTOTAL(109,raports_8[Opening balance]) -> #REF! | D9: =SUBTOTAL(109,raports_8[Operation]) -> 390.5 | E9: =SUBTOTAL(109,raports_8[Closing balance]) -> #REF! | J9: Salary | K9: =SUMIFS(operations[Amount],operations[Category],Table9162832364044[[#This Row],[Category]],operations[Month],'1'!$B$12) -> 4500 | N9: Expense
J10: Scholarship | K10: =SUMIFS(operations[Amount],operations[Category],Table9162832364044[[#This Row],[Category]],operations[Month],'1'!$B$12) -> 0 | N10: Expense
J11: Transfer | K11: =SUMIFS(operations[Amount],operations[Category],Table9162832364044[[#This Row],[Category]],operations[Month],'1'!$B$12) -> 0 | N11: Income
A12: Month | B12: {=_xlfn.TEXTAFTER(CELL("filename",A1),"]")} -> 8 | J12: Total | K12: =SUBTOTAL(109,Table9162832364044[Total]) -> 5475.5 | N12: Income
N13: Income
A14: Type | B14: Total | N14: Income
A15: Income | B15: =SUMIFS(operations[Amount],operations[Type],balance_8[[#This Row],[Type]],operations[Month],'1'!$B$12) -> 5655.5 | N15: Income
A16: Expense | B16: =SUMIFS(operations[Amount],operations[Type],balance_8[[#This Row],[Type]],operations[Month],'1'!$B$12) -> -4810 | N16: Income
A17: Transfer | B17: =SUMIFS(operations[Amount],operations[Type],balance_8[[#This Row],[Type]],operations[Month],'1'!$B$12) -> 0 | N17: Transfer
A18: Total | B18: =SUBTOTAL(109,balance_8[Total]) -> 845.5

Sheet 7
A1: Bank | B1: Product | C1: Opening balance | D1: Operation | E1: Closing balance | G1: Category | H1: Total | J1: Category | K1: Total | N1: Type
